Workbook

Sheet SITUATION14.15
A1: N° Com. | B1: ND | C1: S. Produit | D1: Etat | E1: Op | F1: Motif | G1: com. motif | H1: Délai(j) | I1: Intitulé client | J1: Contact client | K1: Adresse | L1: A
A2: DTLI70641411 | B2: 0529418093 | C2: RTC DTL | D2: VA | E2: NA | H2: 206.85321 | I2: WNA_ | J2: 0641373034 | K2: M'HAMID ,Lotissement Al Housna ,Porte 372 | L2: =VLOOKUP(A2,[1]MOTIF!$B:$F,1,0) -> #N/A
A3: DTLI70727850 | B3: 0529609744 | C3: RTC DTL | D3: VA | E3: NA | F3: CRI | H3: 181.73317 | I3: WNA_ | J3: 0671369895 | K3: BOUAAKAZ , Opération Bahia Sakane Imm 64 ,Numéro 19 | L3: =VLOOKUP(A3,[1]MOTIF!$B:$F,1,0) -> DTLI70727850
A4: DTLI70734641 | B4: 0529647012 | C4: RTC DTL | D4: VA | E4: NA | H4: 178.78765 | I4: WNA_ | J4: 0708917890 | K4: M'HAMID , Les jardins d Abrar GH3-Imm28 ,Numéro 29 | L4: =VLOOKUP(A4,[1]MOTIF!$B:$F,1,0) -> DTLI70734641
A5: DTLIO00BBED7 | B5: 0520960948 | C5: RTC DTL | D5: VA | E5: NA | H5: 173.19597 | I5: MARMT_ | J5: 0641080135 | K5: M'HAMID , Lotissement Berradi II ,Numéro 493 | L5: =VLOOKUP(A5,[1]MOTIF!$B:$F,1,0) -> DTLIO00BBED7
A6: DTLI70808185 | B6: 0529580630 | C6: RTC DTL | D6: VA | E6: NA | H6: 154.04946 | I6: WNA_ | J6: 0626972101 | K6: M'HAMID , Bloc 19 ,Numéro 725 | L6: =VLOOKUP(A6,[1]MOTIF!$B:$F,1,0) -> DTLI70808185
A7: DTLI70815011 | B7: 0529591519 | C7: RTC DTL | D7: VA | E7: NA | H7: 151.89081 | I7: WNA_ | J7: 0624096534 | K7: M'HAMID , Op Abwab Al Atlas Imm B3 ,Numéro 40 | L7: =VLOOKUP(A7,[1]MOTIF!$B:$F,1,0) -> DTLI70815011
A8: DTLI70822536 | B8: 0529410591 | C8: RTC DTL | D8: VA | E8: NA | H8: 149.10561 | I8: WNA_ | J8: 0696365109 | K8: BOUAAKAZ ,Bloc 12 ,Numéro 583 | L8: =VLOOKUP(A8,[1]MOTIF!$B:$F,1,0) -> DTLI70822536
A9: DTLI70823120 | B9: 0529429466 | C9: RTC DTL | D9: VA | E9: NA | H9: 148.98858 | I9: WNA_ | J9: 212661744871 | K9: BOUAAKAZ , Opération Bahia Sakane Imm 73 ,Numéro 1065 | L9: =VLOOKUP(A9,[1]MOTIF!$B:$F,1,0) -> DTLI70823120
A10: DTLI70831392 | B10: 0529432499 | C10: RTC DTL | D10: VA | E10: NA | H10: 146.85287 | I10: WNA_ | J10: 0694778288 | K10: Province M'HAMID ,Opération les Jardins d'Anas Imm E1 ,Numéro 18 | L10: =VLOOKUP(A10,[1]MOTIF!$B:$F,1,0) -> DTLI70831392
A11: DTLI70834878 | B11: 0529440893 | C11: RTC DTL | D11: VA | E11: NA | H11: 144.75255 | I11: WNA_ | J11: 212661940825 | K11: M'HAMID , Opération Diour Atlas Imm V ,Numéro 11 Bat imm w | L11: =VLOOKUP(A11,[1]MOTIF!$B:$F,1,0) -> DTLI70834878
A12: DTLI70848819 | B12: 0529445356 | C12: RTC DTL | D12: VA | E12: NA | H12: 140.86694 | I12: WNA_ | J12: 0669334904 | K12: M'HAMID , Les jardins d Abrar GH5-Imm47 ,Numéro 5 | L12: =VLOOKUP(A12,[1]MOTIF!$B:$F,1,0) -> #N/A
A13: DTLI70855365 | B13: 0529447317 | C13: RTC DTL | D13: VA | E13: NA | H13: 138.11986 | I13: WNA_ | J13: 212670423087 | K13: M'HAMID ,Lotissement Saada 2 ,Numéro 863 | L13: =VLOOKUP(A13,[1]MOTIF!$B:$F,1,0) -> DTLI70855365
A14: DTLIO00C5AD5 | B14: 0525294318 | C14: RTC DTL | D14: VA | E14: NA | H14: 137.87559 | I14: MARMT_ | J14: 0684466786 | K14: M'HAMID , Opération Diour Atlas Imm J ,Numéro 12 Bat IMM V | L14: =VLOOKUP(A14,[1]MOTIF!$B:$F,1,0) -> DTLIO00C5AD5
A15: DTLIO00C5738 | B15: 0525294069 | C15: RTC DTL | D15: VA | E15: NA | H15: 137.23554 | I15: MARMT_ | J15: 0634669071 | K15: M'HAMID ,Opération Al Bassatine Bloc A ,Numéro 1 Bat 15 | L15: =VLOOKUP(A15,[1]MOTIF!$B:$F,1,0) -> DTLIO00C5738
... A42: DTLI70994638 | B42: 0529712093 | C42: RTC DTL | D42: VA | E42: NA | H42: 89.045914 | I42: WNA_ | J42: 0648684341 | K42: M'HAMID ,Bloc 26 ,Numéro 1191 | L42: =VLOOKUP(A42,[1]MOTIF!$B:$F,1,0) -> DTLI70994638
A43: 99407301 | B43: 524379905 | C43: RTC | D43: VA | E43: NA | F43: EBST | H43: 88.204074 | I43: AOUTARABDELALI | J43: 0661746605 | K43: M'HAMID ,Bassatine Mrkch GH4-Imm 20U Mhamid9 ,Numéro 5 Etage 3
A44: DTLI70996673 | B44: 0529712877 | C44: RTC DTL | D44: VA | E44: NA | H44: 88.116748 | I44: WNA_ | J44: 212635710367 | K44: M'HAMID , Opération Salama GHI-Imm3 ,Numéro 3 Bat BLOC H IMM 03 | L44: =VLOOKUP(A44,[1]MOTIF!$B:$F,1,0) -> DTLI70996673
A45: DTLI70997241 | B45: 0529713551 | C45: RTC DTL | D45: VA | E45: NA | H45: 88.046771 | I45: WNA_ | J45: 0657162022 | K45: M'HAMID ,Lotissement Al Housna ,Numéro 464 | L45: =VLOOKUP(A45,[1]MOTIF!$B:$F,1,0) -> DTLI70997241
A46: DTLI70998954 | B46: 0529714279 | C46: RTC DTL | D46: VA | E46: NA | H46: 87.129711 | I46: WNA_ | J46: 212660971142 | K46: M'HAMID ,Lotissement Saada 1 ,Numéro 445 | L46: =VLOOKUP(A46,[1]MOTIF!$B:$F,1,0) -> DTLI70998954
A47: DTLI71003402 | B47: 0529715890 | C47: RTC DTL | D47: VA | E47: NA | H47: 85.687222 | I47: WNA_ | J47: 0601409696 | K47: M'HAMID , Lotissement M hamid 2 ,Numéro 1564 | L47: =VLOOKUP(A47,[1]MOTIF!$B:$F,1,0) -> DTLI71003402
A48: DTLI71014644 | B48: 0529719258 | C48: RTC DTL | D48: VA | E48: NA | H48: 80.723704 | I48: WNA_ | J48: 0663298214 | K48: BOUAAKAZ , Voie Inconnue ,Numéro RES KORTOBA IMM F N 8 | L48: =VLOOKUP(A48,[1]MOTIF!$B:$F,1,0) -> #N/A
A49: DTLI71030474 | B49: 0529724741 | C49: RTC DTL | D49: VA | E49: NA | H49: 72.159086 | I49: WNA_ | J49: 212632774634 | K49: M'HAMID , Lotissement M'hamid 9 ,Numéro 509 | L49: =VLOOKUP(A49,[1]MOTIF!$B:$F,1,0) -> DTLI71030474
A50: DTLI71034419 | B50: 0529726562 | C50: RTC DTL | D50: VA | E50: NA | H50: 70.882292 | I50: WNA_ | J50: 0616242750 | K50: M'HAMID , Opération Abwab Al Atlas Imm B6 ,Numéro 11 Bat IMM B9 | L50: =VLOOKUP(A50,[1]MOTIF!$B:$F,1,0) -> DTLI71034419
A51: DTLI71036742 | B51: 0529728168 | C51: RTC DTL | D51: VA | E51: NA | H51: 69.734653 | I51: WNA_ | J51: 0626372353 | K51: M'HAMID ,Lotissement M hamid 4 ,Numéro 499 | L51: =VLOOKUP(A51,[1]MOTIF!$B:$F,1,0) -> DTLI71036742
A52: DTLI02206624 | B52: 0529715759 | C52: RTC DTL | D52: VA | E52: NA | H52: 66.961725 | I52: WNA_ | J52: 212667237667 | K52: M'HAMID , Lotissement M hamid 2 ,Numéro 24 | L52: =VLOOKUP(A52,[1]MOTIF!$B:$F,1,0) -> DTLI02206624
A53: 99482279 | B53: 0524361444 | C53: RTC | D53: VA | E53: TR | H53: 65.261377 | I53: EDDACHRAOUIFATIMA | J53: 000000000 | K53: M'HAMID ,Op-Jardins des Orangier Imm D2 ,Etage 1 Porte 8
A54: DTLI71045690 | B54: 0529717351 | C54: RTC DTL | D54: VA | E54: NA | H54: 65.200914 | I54: WNA_ | J54: 0701201631 | K54: M'HAMID ,Lotissement Adrar I ,Numéro 60 | L54: =VLOOKUP(A54,[1]MOTIF!$B:$F,1,0) -> DTLI71045690
A55: DTLI02206981 | B55: 0529737462 | C55: RTC DTL | D55: VA | E55: NA | H55: 60.855185 | I55: WNA_ | J55: 212630870058 | K55: M'HAMID ,Lotissement Saada 1 ,Numéro 368 | L55: =VLOOKUP(A55,[1]MOTIF!$B:$F,1,0) -> DTLI02206981
A56: DTLI71057362 | B56: 0529720428 | C56: RTC DTL | D56: VA | E56: NA | F56: TRSA | G56: TR saturé Mha:142 | H56: 60.799606 | I56: WNA_ | J56: 212663804910 | K56: BOUAAKAZ , Opération Bahia Sakane Imm 69 ,Numéro 3220 | L56: =VLOOKUP(A56,[1]MOTIF!$B:$F,1,0) -> DTLI71057362
A57: DTLI71065037 | B57: 0529740107 | C57: RTC DTL | D57: VA | E57: NA | H57: 58.896493 | I57: WNA_ | J57: 0662845144 | K57: OPERATION DOHA BORJ AZZAYTOUN , Immeuble GH01-004 ,Numéro imm 4 Bat 10 | L57: =VLOOKUP(A57,[1]MOTIF!$B:$F,1,0) -> DTLI71065037
A58: DTLIO00DA619 | B58: 0525316158 | C58: RTC DTL | D58: VA | E58: NA | H58: 58.167072 | I58: MARMT_ | J58: 0615334752 | K58: M'HAMID ,Résidence Noha GH3 Imm 4 ,Numéro 45 Bat 15 | L58: =VLOOKUP(A58,[1]MOTIF!$B:$F,1,0) -> DTLIO00DA619
A59: DTLI71068038 | B59: 0529590306 | C59: RTC DTL | D59: VA | E59: NA | H59: 58.155243 | I59: WNA_ | J59: 212661183621 | K59: M'HAMID , Opération les Jardins d'Anas ,Numéro imm o Bat 1 | L59: =VLOOKUP(A59,[1]MOTIF!$B:$F,1,0) -> DTLI71068038
A60: DTLI71070897 | B60: 0529440699 | C60: RTC DTL | D60: VA | E60: NA | H60: 57.142361 | I60: WNA_ | J60: 0771555499 | K60: M'HAMID ,Lotissement M'hamid 9 ,Numéro 74 | L60: =VLOOKUP(A60,[1]MOTIF!$B:$F,1,0) -> DTLI71070897
A61: DTLI71074202 | B61: 0529744104 | C61: RTC DTL | D61: VA | E61: NA | H61: 56.008264 | I61: WNA_ | J61: 0662778805 | K61: M'HAMID ,Lotissement M hamid 5 ,Numéro 1066 | L61: =VLOOKUP(A61,[1]MOTIF!$B:$F,1,0) -> DTLI71074202
A62: DTLI71078058 | B62: 0529737599 | C62: RTC DTL | D62: VA | E62: NA | H62: 53.883322 | I62: WNA_ | J62: 212626288009 | K62: M'HAMID , Opération El Bahja ,Numéro 9 | L62: =VLOOKUP(A62,[1]MOTIF!$B:$F,1,0) -> DTLI71078058
A63: DTLIO00DBB63 | B63: 0525317504 | C63: RTC DTL | D63: VA | E63: NA | H63: 52.96162 | I63: MARMT_ | J63: 0670417703 | K63: M'HAMID ,Lotissement Maatallah ,Numéro 2257 Bat 15 | L63: =VLOOKUP(A63,[1]MOTIF!$B:$F,1,0) -> #N/A
A64: DTLI71081239 | B64: 0529744272 | C64: RTC DTL | D64: VA | E64: NA | H64: 52.208738 | I64: WNA_ | J64: 212696175750 | K64: M'HAMID , Opération Borj Ali Imm A M'hamid 9 ,Numéro 5 | L64: =VLOOKUP(A64,[1]MOTIF!$B:$F,1,0) -> #N/A
A65: DTLI71082468 | B65: 0529451947 | C65: RTC DTL | D65: VA | E65: NA | H65: 51.962326 | I65: WNA_ | J65: 0666732403 | K65: M'HAMID ,Lotissement Maatallah ,Numéro 74 | L65: =VLOOKUP(A65,[1]MOTIF!$B:$F,1,0) -> DTLI71082468
A66: DTLI71086760 | B66: 0529751247 | C66: RTC DTL | D66: VA | E66: NA | H66: 50.977454 | I66: WNA_ | J66: 0633211649 | K66: M'HAMID , Lotissement Berradi II ,Numéro 610 | L66: =VLOOKUP(A66,[1]MOTIF!$B:$F,1,0) -> DTLI71086760
...

Sheet SITUATION16
A1: N° Com. | B1: ND | C1: S. Produit | D1: Etat | E1: Op | F1: Motif | G1: com. motif | H1: Délai(j) | I1: Intitulé client | J1: Contact client | K1: Adresse | L1: A
A2: DTLI70641411 | B2: 0529418093 | C2: RTC DTL | D2: VA | E2: NA | H2: 208.5136 | I2: WNA_ | J2: 0641373034 | K2: M'HAMID ,Lotissement Al Housna ,Porte 372 | L2: =VLOOKUP(A2,#REF!,1,0) -> #REF!
A3: DTLI70727850 | B3: 0529609744 | C3: RTC DTL | D3: VA | E3: NA | F3: CRI | H3: 183.39356 | I3: WNA_ | J3: 0671369895 | K3: BOUAAKAZ , Opération Bahia Sakane Imm 64 ,Numéro 19 | L3: =VLOOKUP(A3,#REF!,1,0) -> #REF!
A4: DTLI70734641 | B4: 0529647012 | C4: RTC DTL | D4: VA | E4: NA | H4: 180.44804 | I4: WNA_ | J4: 0708917890 | K4: M'HAMID , Les jardins d Abrar GH3-Imm28 ,Numéro 29 | L4: =VLOOKUP(A4,#REF!,1,0) -> #REF!
A5: DTLIO00BBED7 | B5: 0520960948 | C5: RTC DTL | D5: VA | E5: NA | H5: 174.85637 | I5: MARMT_ | J5: 0641080135 | K5: M'HAMID , Lotissement Berradi II ,Numéro 493 | L5: =VLOOKUP(A5,#REF!,1,0) -> #REF!
A6: DTLI70808185 | B6: 0529580630 | C6: RTC DTL | D6: VA | E6: NA | H6: 155.70985 | I6: WNA_ | J6: 0626972101 | K6: M'HAMID , Bloc 19 ,Numéro 725 | L6: =VLOOKUP(A6,#REF!,1,0) -> #REF!
A7: DTLI70815011 | B7: 0529591519 | C7: RTC DTL | D7: VA | E7: NA | H7: 153.5512 | I7: WNA_ | J7: 0624096534 | K7: M'HAMID , Op Abwab Al Atlas Imm B3 ,Numéro 40 | L7: =VLOOKUP(A7,#REF!,1,0) -> #REF!
A8: DTLI70822536 | B8: 0529410591 | C8: RTC DTL | D8: VA | E8: NA | H8: 150.76601 | I8: WNA_ | J8: 0696365109 | K8: BOUAAKAZ ,Bloc 12 ,Numéro 583 | L8: =VLOOKUP(A8,#REF!,1,0) -> #REF!
A9: DTLI70823120 | B9: 0529429466 | C9: RTC DTL | D9: VA | E9: NA | H9: 150.64897 | I9: WNA_ | J9: 212661744871 | K9: BOUAAKAZ , Opération Bahia Sakane Imm 73 ,Numéro 1065 | L9: =VLOOKUP(A9,#REF!,1,0) -> #REF!
A10: DTLI70831392 | B10: 0529432499 | C10: RTC DTL | D10: VA | E10: NA | H10: 148.51326 | I10: WNA_ | J10: 0694778288 | K10: Province M'HAMID ,Opération les Jardins d'Anas Imm E1 ,Numéro 18 | L10: =VLOOKUP(A10,#REF!,1,0) -> #REF!
A11: DTLI70834878 | B11: 0529440893 | C11: RTC DTL | D11: VA | E11: NA | H11: 146.41294 | I11: WNA_ | J11: 212661940825 | K11: M'HAMID , Opération Diour Atlas Imm V ,Numéro 11 Bat imm w | L11: =VLOOKUP(A11,#REF!,1,0) -> #REF!
A12: DTLI70848819 | B12: 0529445356 | C12: RTC DTL | D12: VA | E12: NA | H12: 142.52734 | I12: WNA_ | J12: 0669334904 | K12: M'HAMID , Les jardins d Abrar GH5-Imm47 ,Numéro 5 | L12: =VLOOKUP(A12,#REF!,1,0) -> #REF!
A13: DTLI70855365 | B13: 0529447317 | C13: RTC DTL | D13: VA | E13: NA | H13: 139.78025 | I13: WNA_ | J13: 212670423087 | K13: M'HAMID ,Lotissement Saada 2 ,Numéro 863 | L13: =VLOOKUP(A13,#REF!,1,0) -> #REF!
A14: DTLIO00C5AD5 | B14: 0525294318 | C14: RTC DTL | D14: VA | E14: NA | H14: 139.53598 | I14: MARMT_ | J14: 0684466786 | K14: M'HAMID , Opération Diour Atlas Imm J ,Numéro 12 Bat IMM V | L14: =VLOOKUP(A14,#REF!,1,0) -> #REF!
A15: DTLIO00C5738 | B15: 0525294069 | C15: RTC DTL | D15: VA | E15: NA | H15: 138.89594 | I15: MARMT_ | J15: 0634669071 | K15: M'HAMID ,Opération Al Bassatine Bloc A ,Numéro 1 Bat 15 | L15: =VLOOKUP(A15,#REF!,1,0) -> #REF!
... A42: DTLI70994638 | B42: 0529712093 | C42: RTC DTL | D42: VA | E42: NA | H42: 90.706308 | I42: WNA_ | J42: 0648684341 | K42: M'HAMID ,Bloc 26 ,Numéro 1191 | L42: =VLOOKUP(A42,#REF!,1,0) -> #REF!
A43: 99407301 | B43: 0524379905 | C43: RTC | D43: VA | E43: NA | F43: EBST | H43: 89.864468 | I43: AOUTARABDELALI | J43: 0661746605 | K43: M'HAMID ,Bassatine Mrkch GH4-Imm 20U Mhamid9 ,Numéro 5 Etage 3
A44: DTLI70996673 | B44: 0529712877 | C44: RTC DTL | D44: VA | E44: NA | H44: 89.777141 | I44: WNA_ | J44: 212635710367 | K44: M'HAMID , Opération Salama GHI-Imm3 ,Numéro 3 Bat BLOC H IMM 03 | L44: =VLOOKUP(A44,#REF!,1,0) -> #REF!
A45: DTLI70997241 | B45: 0529713551 | C45: RTC DTL | D45: VA | E45: NA | H45: 89.707164 | I45: WNA_ | J45: 0657162022 | K45: M'HAMID ,Lotissement Al Housna ,Numéro 464 | L45: =VLOOKUP(A45,#REF!,1,0) -> #REF!
A46: DTLI70998954 | B46: 0529714279 | C46: RTC DTL | D46: VA | E46: NA | H46: 88.790104 | I46: WNA_ | J46: 212660971142 | K46: M'HAMID ,Lotissement Saada 1 ,Numéro 445 | L46: =VLOOKUP(A46,#REF!,1,0) -> #REF!
A47: DTLI71003402 | B47: 0529715890 | C47: RTC DTL | D47: VA | E47: NA | H47: 87.347616 | I47: WNA_ | J47: 0601409696 | K47: M'HAMID , Lotissement M hamid 2 ,Numéro 1564 | L47: =VLOOKUP(A47,#REF!,1,0) -> #REF!
A48: DTLI71014644 | B48: 0529719258 | C48: RTC DTL | D48: VA | E48: NA | H48: 82.384097 | I48: WNA_ | J48: 0663298214 | K48: BOUAAKAZ , Voie Inconnue ,Numéro RES KORTOBA IMM F N 8 | L48: =VLOOKUP(A48,#REF!,1,0) -> #REF!
A49: DTLI71030474 | B49: 0529724741 | C49: RTC DTL | D49: VA | E49: NA | H49: 73.819479 | I49: WNA_ | J49: 212632774634 | K49: M'HAMID , Lotissement M'hamid 9 ,Numéro 509 | L49: =VLOOKUP(A49,#REF!,1,0) -> #REF!
A50: DTLI71034419 | B50: 0529726562 | C50: RTC DTL | D50: VA | E50: NA | H50: 72.542685 | I50: WNA_ | J50: 0616242750 | K50: M'HAMID , Opération Abwab Al Atlas Imm B6 ,Numéro 11 Bat IMM B9 | L50: =VLOOKUP(A50,#REF!,1,0) -> #REF!
A51: DTLI71036742 | B51: 0529728168 | C51: RTC DTL | D51: VA | E51: NA | H51: 71.395046 | I51: WNA_ | J51: 0626372353 | K51: M'HAMID ,Lotissement M hamid 4 ,Numéro 499 | L51: =VLOOKUP(A51,#REF!,1,0) -> #REF!
A52: DTLI02206624 | B52: 0529715759 | C52: RTC DTL | D52: VA | E52: NA | H52: 68.622118 | I52: WNA_ | J52: 212667237667 | K52: M'HAMID , Lotissement M hamid 2 ,Numéro 24 | L52: =VLOOKUP(A52,#REF!,1,0) -> #REF!
A53: 99482279 | B53: 0524361444 | C53: RTC | D53: VA | E53: TR | H53: 66.921771 | I53: EDDACHRAOUIFATIMA | J53: 000000000 | K53: M'HAMID ,Op-Jardins des Orangier Imm D2 ,Etage 1 Porte 8
A54: DTLI71045690 | B54: 0529717351 | C54: RTC DTL | D54: VA | E54: NA | H54: 66.861308 | I54: WNA_ | J54: 0701201631 | K54: M'HAMID ,Lotissement Adrar I ,Numéro 60 | L54: =VLOOKUP(A54,#REF!,1,0) -> #REF!
A55: DTLI02206981 | B55: 0529737462 | C55: RTC DTL | D55: VA | E55: NA | H55: 62.515579 | I55: WNA_ | J55: 212630870058 | K55: M'HAMID ,Lotissement Saada 1 ,Numéro 368 | L55: =VLOOKUP(A55,#REF!,1,0) -> #REF!
A56: DTLI71057362 | B56: 0529720428 | C56: RTC DTL | D56: VA | E56: NA | F56: TRSA | G56: TR saturé Mha:142 | H56: 62.46 | I56: WNA_ | J56: 212663804910 | K56: BOUAAKAZ , Opération Bahia Sakane Imm 69 ,Numéro 3220 | L56: =VLOOKUP(A56,#REF!,1,0) -> #REF!
A57: DTLI71065037 | B57: 0529740107 | C57: RTC DTL | D57: VA | E57: NA | H57: 60.556887 | I57: WNA_ | J57: 0662845144 | K57: OPERATION DOHA BORJ AZZAYTOUN , Immeuble GH01-004 ,Numéro imm 4 Bat 10 | L57: =VLOOKUP(A57,#REF!,1,0) -> #REF!
A58: DTLIO00DA619 | B58: 0525316158 | C58: RTC DTL | D58: VA | E58: NA | H58: 59.827465 | I58: MARMT_ | J58: 0615334752 | K58: M'HAMID ,Résidence Noha GH3 Imm 4 ,Numéro 45 Bat 15 | L58: =VLOOKUP(A58,#REF!,1,0) -> #REF!
A59: DTLI71068038 | B59: 0529590306 | C59: RTC DTL | D59: VA | E59: NA | H59: 59.815637 | I59: WNA_ | J59: 212661183621 | K59: M'HAMID , Opération les Jardins d'Anas ,Numéro imm o Bat 1 | L59: =VLOOKUP(A59,#REF!,1,0) -> #REF!
A60: DTLI71070897 | B60: 0529440699 | C60: RTC DTL | D60: VA | E60: NA | H60: 58.802755 | I60: WNA_ | J60: 0771555499 | K60: M'HAMID ,Lotissement M'hamid 9 ,Numéro 74 | L60: =VLOOKUP(A60,#REF!,1,0) -> #REF!
A61: DTLI71074202 | B61: 0529744104 | C61: RTC DTL | D61: VA | E61: NA | H61: 57.668657 | I61: WNA_ | J61: 0662778805 | K61: M'HAMID ,Lotissement M hamid 5 ,Numéro 1066 | L61: =VLOOKUP(A61,#REF!,1,0) -> #REF!
A62: DTLI71078058 | B62: 0529737599 | C62: RTC DTL | D62: VA | E62: NA | H62: 55.543715 | I62: WNA_ | J62: 212626288009 | K62: M'HAMID , Opération El Bahja ,Numéro 9 | L62: =VLOOKUP(A62,#REF!,1,0) -> #REF!
A63: DTLIO00DBB63 | B63: 0525317504 | C63: RTC DTL | D63: VA | E63: NA | H63: 54.622014 | I63: MARMT_ | J63: 0670417703 | K63: M'HAMID ,Lotissement Maatallah ,Numéro 2257 Bat 15 | L63: =VLOOKUP(A63,#REF!,1,0) -> #REF!
A64: DTLI71081239 | B64: 0529744272 | C64: RTC DTL | D64: VA | E64: NA | H64: 53.869132 | I64: WNA_ | J64: 212696175750 | K64: M'HAMID , Opération Borj Ali Imm A M'hamid 9 ,Numéro 5 | L64: =VLOOKUP(A64,#REF!,1,0) -> #REF!
A65: DTLI71082468 | B65: 0529451947 | C65: RTC DTL | D65: VA | E65: NA | H65: 53.62272 | I65: WNA_ | J65: 0666732403 | K65: M'HAMID ,Lotissement Maatallah ,Numéro 74 | L65: =VLOOKUP(A65,#REF!,1,0) -> #REF!
A66: DTLI71086760 | B66: 0529751247 | C66: RTC DTL | D66: VA | E66: NA | H66: 52.637847 | I66: WNA_ | J66: 0633211649 | K66: M'HAMID , Lotissement Berradi II ,Numéro 610 | L66: =VLOOKUP(A66,#REF!,1,0) -> #REF!
...

Sheet SITUATION17
A1: N° Com. | B1: ND | C1: S. Produit | D1: Etat | E1: Op | F1: Motif | G1: com. motif | H1: Délai(j) | I1: Intitulé client | J1: Contact client | K1: Adresse | L1: A
A2: DTLI70641411 | B2: 529418093 | C2: RTC DTL | D2: VA | E2: NA | H2: 209.51396 | I2: WNA_ | J2: 0641373034 | K2: M'HAMID ,Lotissement Al Housna ,Porte 372 | L2: =VLOOKUP(A2,#REF!,1,0) -> #REF!
A3: DTLI70727850 | B3: 529609744 | C3: RTC DTL | D3: VA | E3: NA | F3: CRI | H3: 184.39392 | I3: WNA_ | J3: 0671369895 | K3: BOUAAKAZ , Opération Bahia Sakane Imm 64 ,Numéro 19 | L3: =VLOOKUP(A3,#REF!,1,0) -> #REF!
A4: DTLI70734641 | B4: 529647012 | C4: RTC DTL | D4: VA | E4: NA | H4: 181.4484 | I4: WNA_ | J4: 0708917890 | K4: M'HAMID , Les jardins d Abrar GH3-Imm28 ,Numéro 29 | L4: =VLOOKUP(A4,#REF!,1,0) -> #REF!
A5: DTLIO00BBED7 | B5: 520960948 | C5: RTC DTL | D5: VA | E5: NA | H5: 175.85672 | I5: MARMT_ | J5: 0641080135 | K5: M'HAMID , Lotissement Berradi II ,Numéro 493 | L5: =VLOOKUP(A5,#REF!,1,0) -> #REF!
A6: DTLI70808185 | B6: 529580630 | C6: RTC DTL | D6: VA | E6: NA | H6: 156.71021 | I6: WNA_ | J6: 0626972101 | K6: M'HAMID , Bloc 19 ,Numéro 725 | L6: =VLOOKUP(A6,#REF!,1,0) -> #REF!
A7: DTLI70815011 | B7: 529591519 | C7: RTC DTL | D7: VA | E7: NA | H7: 154.55156 | I7: WNA_ | J7: 0624096534 | K7: M'HAMID , Op Abwab Al Atlas Imm B3 ,Numéro 40 | L7: =VLOOKUP(A7,#REF!,1,0) -> #REF!
A8: DTLI70822536 | B8: 529410591 | C8: RTC DTL | D8: VA | E8: NA | H8: 151.76637 | I8: WNA_ | J8: 0696365109 | K8: BOUAAKAZ ,Bloc 12 ,Numéro 583 | L8: =VLOOKUP(A8,#REF!,1,0) -> #REF!
A9: DTLI70823120 | B9: 529429466 | C9: RTC DTL | D9: VA | E9: NA | H9: 151.64933 | I9: WNA_ | J9: 212661744871 | K9: BOUAAKAZ , Opération Bahia Sakane Imm 73 ,Numéro 1065 | L9: =VLOOKUP(A9,#REF!,1,0) -> #REF!
A10: DTLI70831392 | B10: 529432499 | C10: RTC DTL | D10: VA | E10: NA | H10: 149.51362 | I10: WNA_ | J10: 0694778288 | K10: Province M'HAMID ,Opération les Jardins d'Anas Imm E1 ,Numéro 18 | L10: =VLOOKUP(A10,#REF!,1,0) -> #REF!
A11: DTLI70834878 | B11: 529440893 | C11: RTC DTL | D11: VA | E11: NA | H11: 147.4133 | I11: WNA_ | J11: 212661940825 | K11: M'HAMID , Opération Diour Atlas Imm V ,Numéro 11 Bat imm w | L11: =VLOOKUP(A11,#REF!,1,0) -> #REF!
A12: DTLI70848819 | B12: 529445356 | C12: RTC DTL | D12: VA | E12: NA | H12: 143.5277 | I12: WNA_ | J12: 0669334904 | K12: M'HAMID , Les jardins d Abrar GH5-Imm47 ,Numéro 5 | L12: =VLOOKUP(A12,#REF!,1,0) -> #REF!
A13: DTLI70855365 | B13: 529447317 | C13: RTC DTL | D13: VA | E13: NA | H13: 140.78061 | I13: WNA_ | J13: 212670423087 | K13: M'HAMID ,Lotissement Saada 2 ,Numéro 863 | L13: =VLOOKUP(A13,#REF!,1,0) -> #REF!
A14: DTLIO00C5AD5 | B14: 525294318 | C14: RTC DTL | D14: VA | E14: NA | H14: 140.53634 | I14: MARMT_ | J14: 0684466786 | K14: M'HAMID , Opération Diour Atlas Imm J ,Numéro 12 Bat IMM V | L14: =VLOOKUP(A14,#REF!,1,0) -> #REF!
A15: DTLIO00C5738 | B15: 525294069 | C15: RTC DTL | D15: VA | E15: NA | H15: 139.8963 | I15: MARMT_ | J15: 0634669071 | K15: M'HAMID ,Opération Al Bassatine Bloc A ,Numéro 1 Bat 15 | L15: =VLOOKUP(A15,#REF!,1,0) -> #REF!
... A42: DTLI70994638 | B42: 529712093 | C42: RTC DTL | D42: VA | E42: NA | H42: 91.706667 | I42: WNA_ | J42: 0648684341 | K42: M'HAMID ,Bloc 26 ,Numéro 1191 | L42: =VLOOKUP(A42,#REF!,1,0) -> #REF!
A43: 99407301 | B43: 524379905 | C43: RTC | D43: VA | E43: NA | F43: EBST | H43: 90.864826 | I43: AOUTARABDELALI | J43: 0661746605 | K43: M'HAMID ,Bassatine Mrkch GH4-Imm 20U Mhamid9 ,Numéro 5 Etage 3
A44: DTLI70996673 | B44: 529712877 | C44: RTC DTL | D44: VA | E44: NA | H44: 90.7775 | I44: WNA_ | J44: 212635710367 | K44: M'HAMID , Opération Salama GHI-Imm3 ,Numéro 3 Bat BLOC H IMM 03 | L44: =VLOOKUP(A44,#REF!,1,0) -> #REF!
A45: DTLI70997241 | B45: 529713551 | C45: RTC DTL | D45: VA | E45: NA | H45: 90.707523 | I45: WNA_ | J45: 0657162022 | K45: M'HAMID ,Lotissement Al Housna ,Numéro 464 | L45: =VLOOKUP(A45,#REF!,1,0) -> #REF!
A46: DTLI70998954 | B46: 529714279 | C46: RTC DTL | D46: VA | E46: NA | H46: 89.790463 | I46: WNA_ | J46: 212660971142 | K46: M'HAMID ,Lotissement Saada 1 ,Numéro 445 | L46: =VLOOKUP(A46,#REF!,1,0) -> #REF!
A47: DTLI71003402 | B47: 529715890 | C47: RTC DTL | D47: VA | E47: NA | H47: 88.347975 | I47: WNA_ | J47: 0601409696 | K47: M'HAMID , Lotissement M hamid 2 ,Numéro 1564 | L47: =VLOOKUP(A47,#REF!,1,0) -> #REF!
A48: DTLI71014644 | B48: 529719258 | C48: RTC DTL | D48: VA | E48: NA | H48: 83.384456 | I48: WNA_ | J48: 0663298214 | K48: BOUAAKAZ , Voie Inconnue ,Numéro RES KORTOBA IMM F N 8 | L48: =VLOOKUP(A48,#REF!,1,0) -> #REF!
A49: DTLI71030474 | B49: 529724741 | C49: RTC DTL | D49: VA | E49: NA | H49: 74.819838 | I49: WNA_ | J49: 212632774634 | K49: M'HAMID , Lotissement M'hamid 9 ,Numéro 509 | L49: =VLOOKUP(A49,#REF!,1,0) -> #REF!
A50: DTLI71034419 | B50: 529726562 | C50: RTC DTL | D50: VA | E50: NA | H50: 73.543044 | I50: WNA_ | J50: 0616242750 | K50: M'HAMID , Opération Abwab Al Atlas Imm B6 ,Numéro 11 Bat IMM B9 | L50: =VLOOKUP(A50,#REF!,1,0) -> #REF!
A51: DTLI71036742 | B51: 529728168 | C51: RTC DTL | D51: VA | E51: NA | H51: 72.395405 | I51: WNA_ | J51: 0626372353 | K51: M'HAMID ,Lotissement M hamid 4 ,Numéro 499 | L51: =VLOOKUP(A51,#REF!,1,0) -> #REF!
A52: DTLI02206624 | B52: 529715759 | C52: RTC DTL | D52: VA | E52: NA | H52: 69.622477 | I52: WNA_ | J52: 212667237667 | K52: M'HAMID , Lotissement M hamid 2 ,Numéro 24 | L52: =VLOOKUP(A52,#REF!,1,0) -> #REF!
A53: 99482279 | B53: 524361444 | C53: RTC | D53: VA | E53: TR | H53: 67.92213 | I53: EDDACHRAOUIFATIMA | J53: 000000000 | K53: M'HAMID ,Op-Jardins des Orangier Imm D2 ,Etage 1 Porte 8
A54: DTLI71045690 | B54: 529717351 | C54: RTC DTL | D54: VA | E54: NA | H54: 67.861667 | I54: WNA_ | J54: 0701201631 | K54: M'HAMID ,Lotissement Adrar I ,Numéro 60 | L54: =VLOOKUP(A54,#REF!,1,0) -> #REF!
A55: DTLI02206981 | B55: 529737462 | C55: RTC DTL | D55: VA | E55: NA | H55: 63.515937 | I55: WNA_ | J55: 212630870058 | K55: M'HAMID ,Lotissement Saada 1 ,Numéro 368 | L55: =VLOOKUP(A55,#REF!,1,0) -> #REF!
A56: DTLI71057362 | B56: 529720428 | C56: RTC DTL | D56: VA | E56: NA | F56: TRSA | G56: TR saturé Mha:142 | H56: 63.460359 | I56: WNA_ | J56: 212663804910 | K56: BOUAAKAZ , Opération Bahia Sakane Imm 69 ,Numéro 3220 | L56: =VLOOKUP(A56,#REF!,1,0) -> #REF!
A57: DTLI71065037 | B57: 529740107 | C57: RTC DTL | D57: VA | E57: NA | H57: 61.557245 | I57: WNA_ | J57: 0662845144 | K57: OPERATION DOHA BORJ AZZAYTOUN , Immeuble GH01-004 ,Numéro imm 4 Bat 10 | L57: =VLOOKUP(A57,#REF!,1,0) -> #REF!
A58: DTLIO00DA619 | B58: 525316158 | C58: RTC DTL | D58: VA | E58: NA | H58: 60.827824 | I58: MARMT_ | J58: 0615334752 | K58: M'HAMID ,Résidence Noha GH3 Imm 4 ,Numéro 45 Bat 15 | L58: =VLOOKUP(A58,#REF!,1,0) -> #REF!
A59: DTLI71068038 | B59: 529590306 | C59: RTC DTL | D59: VA | E59: NA | H59: 60.815995 | I59: WNA_ | J59: 212661183621 | K59: M'HAMID , Opération les Jardins d'Anas ,Numéro imm o Bat 1 | L59: =VLOOKUP(A59,#REF!,1,0) -> #REF!
A60: DTLI71070897 | B60: 529440699 | C60: RTC DTL | D60: VA | E60: NA | H60: 59.803113 | I60: WNA_ | J60: 0771555499 | K60: M'HAMID ,Lotissement M'hamid 9 ,Numéro 74 | L60: =VLOOKUP(A60,#REF!,1,0) -> #REF!
A61: DTLI71074202 | B61: 529744104 | C61: RTC DTL | D61: VA | E61: NA | H61: 58.669016 | I61: WNA_ | J61: 0662778805 | K61: M'HAMID ,Lotissement M hamid 5 ,Numéro 1066 | L61: =VLOOKUP(A61,#REF!,1,0) -> #REF!
A62: DTLI71078058 | B62: 529737599 | C62: RTC DTL | D62: VA | E62: NA | H62: 56.544074 | I62: WNA_ | J62: 212626288009 | K62: M'HAMID , Opération El Bahja ,Numéro 9 | L62: =VLOOKUP(A62,#REF!,1,0) -> #REF!
A63: DTLIO00DBB63 | B63: 525317504 | C63: RTC DTL | D63: VA | E63: NA | H63: 55.622373 | I63: MARMT_ | J63: 0670417703 | K63: M'HAMID ,Lotissement Maatallah ,Numéro 2257 Bat 15 | L63: =VLOOKUP(A63,#REF!,1,0) -> #REF!
A64: DTLI71081239 | B64: 529744272 | C64: RTC DTL | D64: VA | E64: NA | H64: 54.869491 | I64: WNA_ | J64: 212696175750 | K64: M'HAMID , Opération Borj Ali Imm A M'hamid 9 ,Numéro 5 | L64: =VLOOKUP(A64,#REF!,1,0) -> #REF!
A65: DTLI71082468 | B65: 529451947 | C65: RTC DTL | D65: VA | E65: NA | H65: 54.623079 | I65: WNA_ | J65: 0666732403 | K65: M'HAMID ,Lotissement Maatallah ,Numéro 74 | L65: =VLOOKUP(A65,#REF!,1,0) -> #REF!
A66: DTLI71086760 | B66: 529751247 | C66: RTC DTL | D66: VA | E66: NA | H66: 53.638206 | I66: WNA_ | J66: 0633211649 | K66: M'HAMID , Lotissement Berradi II ,Numéro 610 | L66: =VLOOKUP(A66,#REF!,1,0) -> #REF!
...

Sheet SITUIATION18
A1: N° Com. | B1: ND | C1: S. Produit | D1: Etat | E1: Op | F1: Motif | G1: com. motif | H1: Délai(j) | I1: Intitulé client | J1: Contact client | K1: Adresse | L1: A
A2: DTLI70641411 | B2: 0529418093 | C2: RTC DTL | D2: VA | E2: NA | H2: 210.51596 | I2: WNA_ | J2: 0641373034 | K2: M'HAMID ,Lotissement Al Housna ,Porte 372 | L2: =VLOOKUP(A2,#REF!,1,0) -> #REF!
A3: DTLI70727850 | B3: 0529609744 | C3: RTC DTL | D3: VA | E3: NA | F3: CRI | H3: 185.39593 | I3: WNA_ | J3: 0671369895 | K3: BOUAAKAZ , Opération Bahia Sakane Imm 64 ,Numéro 19 | L3: =VLOOKUP(A3,#REF!,1,0) -> #REF!
A4: DTLI70734641 | B4: 0529647012 | C4: RTC DTL | D4: VA | E4: NA | H4: 182.45041 | I4: WNA_ | J4: 0708917890 | K4: M'HAMID , Les jardins d Abrar GH3-Imm28 ,Numéro 29 | L4: =VLOOKUP(A4,#REF!,1,0) -> #REF!
A5: DTLIO00BBED7 | B5: 0520960948 | C5: RTC DTL | D5: VA | E5: NA | H5: 176.85873 | I5: MARMT_ | J5: 0641080135 | K5: M'HAMID , Lotissement Berradi II ,Numéro 493 | L5: =VLOOKUP(A5,#REF!,1,0) -> #REF!
A6: DTLI70808185 | B6: 0529580630 | C6: RTC DTL | D6: VA | E6: NA | H6: 157.71221 | I6: WNA_ | J6: 0626972101 | K6: M'HAMID , Bloc 19 ,Numéro 725 | L6: =VLOOKUP(A6,#REF!,1,0) -> #REF!
A7: DTLI70815011 | B7: 0529591519 | C7: RTC DTL | D7: VA | E7: NA | H7: 155.55356 | I7: WNA_ | J7: 0624096534 | K7: M'HAMID , Op Abwab Al Atlas Imm B3 ,Numéro 40 | L7: =VLOOKUP(A7,#REF!,1,0) -> #REF!
A8: DTLI70822536 | B8: 0529410591 | C8: RTC DTL | D8: VA | E8: NA | H8: 152.76837 | I8: WNA_ | J8: 0696365109 | K8: BOUAAKAZ ,Bloc 12 ,Numéro 583 | L8: =VLOOKUP(A8,#REF!,1,0) -> #REF!
A9: DTLI70823120 | B9: 0529429466 | C9: RTC DTL | D9: VA | E9: NA | H9: 152.65133 | I9: WNA_ | J9: 212661744871 | K9: BOUAAKAZ , Opération Bahia Sakane Imm 73 ,Numéro 1065 | L9: =VLOOKUP(A9,#REF!,1,0) -> #REF!
A10: DTLI70831392 | B10: 0529432499 | C10: RTC DTL | D10: VA | E10: NA | H10: 150.51562 | I10: WNA_ | J10: 0694778288 | K10: Province M'HAMID ,Opération les Jardins d'Anas Imm E1 ,Numéro 18 | L10: =VLOOKUP(A10,#REF!,1,0) -> #REF!
A11: DTLI70834878 | B11: 0529440893 | C11: RTC DTL | D11: VA | E11: NA | H11: 148.4153 | I11: WNA_ | J11: 212661940825 | K11: M'HAMID , Opération Diour Atlas Imm V ,Numéro 11 Bat imm w | L11: =VLOOKUP(A11,#REF!,1,0) -> #REF!
A12: DTLI70848819 | B12: 0529445356 | C12: RTC DTL | D12: VA | E12: NA | H12: 144.5297 | I12: WNA_ | J12: 0669334904 | K12: M'HAMID , Les jardins d Abrar GH5-Imm47 ,Numéro 5 | L12: =VLOOKUP(A12,#REF!,1,0) -> #REF!
A13: DTLI70855365 | B13: 0529447317 | C13: RTC DTL | D13: VA | E13: NA | H13: 141.78262 | I13: WNA_ | J13: 212670423087 | K13: M'HAMID ,Lotissement Saada 2 ,Numéro 863 | L13: =VLOOKUP(A13,#REF!,1,0) -> #REF!
A14: DTLIO00C5AD5 | B14: 0525294318 | C14: RTC DTL | D14: VA | E14: NA | H14: 141.53834 | I14: MARMT_ | J14: 0684466786 | K14: M'HAMID , Opération Diour Atlas Imm J ,Numéro 12 Bat IMM V | L14: =VLOOKUP(A14,#REF!,1,0) -> #REF!
A15: DTLIO00C5738 | B15: 0525294069 | C15: RTC DTL | D15: VA | E15: NA | H15: 140.8983 | I15: MARMT_ | J15: 0634669071 | K15: M'HAMID ,Opération Al Bassatine Bloc A ,Numéro 1 Bat 15 | L15: =VLOOKUP(A15,#REF!,1,0) -> #REF!
... A42: DTLI70994638 | B42: 0529712093 | C42: RTC DTL | D42: VA | E42: NA | H42: 92.708669 | I42: WNA_ | J42: 0648684341 | K42: M'HAMID ,Bloc 26 ,Numéro 1191 | L42: =VLOOKUP(A42,#REF!,1,0) -> #REF!
A43: 99407301 | B43: 0524379905 | C43: RTC | D43: VA | E43: NA | F43: EBST | H43: 91.866829 | I43: AOUTARABDELALI | J43: 0661746605 | K43: M'HAMID ,Bassatine Mrkch GH4-Imm 20U Mhamid9 ,Numéro 5 Etage 3
A44: DTLI70996673 | B44: 0529712877 | C44: RTC DTL | D44: VA | E44: NA | H44: 91.779502 | I44: WNA_ | J44: 212635710367 | K44: M'HAMID , Opération Salama GHI-Imm3 ,Numéro 3 Bat BLOC H IMM 03 | L44: =VLOOKUP(A44,#REF!,1,0) -> #REF!
A45: DTLI70997241 | B45: 0529713551 | C45: RTC DTL | D45: VA | E45: NA | H45: 91.709525 | I45: WNA_ | J45: 0657162022 | K45: M'HAMID ,Lotissement Al Housna ,Numéro 464 | L45: =VLOOKUP(A45,#REF!,1,0) -> #REF!
A46: DTLI70998954 | B46: 0529714279 | C46: RTC DTL | D46: VA | E46: NA | H46: 90.792465 | I46: WNA_ | J46: 212660971142 | K46: M'HAMID ,Lotissement Saada 1 ,Numéro 445 | L46: =VLOOKUP(A46,#REF!,1,0) -> #REF!
A47: DTLI71003402 | B47: 0529715890 | C47: RTC DTL | D47: VA | E47: NA | H47: 89.349977 | I47: WNA_ | J47: 0601409696 | K47: M'HAMID , Lotissement M hamid 2 ,Numéro 1564 | L47: =VLOOKUP(A47,#REF!,1,0) -> #REF!
A48: DTLI71014644 | B48: 0529719258 | C48: RTC DTL | D48: VA | E48: NA | H48: 84.386458 | I48: WNA_ | J48: 0663298214 | K48: BOUAAKAZ , Voie Inconnue ,Numéro RES KORTOBA IMM F N 8 | L48: =VLOOKUP(A48,#REF!,1,0) -> #REF!
A49: DTLI71030474 | B49: 0529724741 | C49: RTC DTL | D49: VA | E49: NA | H49: 75.82184 | I49: WNA_ | J49: 212632774634 | K49: M'HAMID , Lotissement M'hamid 9 ,Numéro 509 | L49: =VLOOKUP(A49,#REF!,1,0) -> #REF!
A50: DTLI71034419 | B50: 0529726562 | C50: RTC DTL | D50: VA | E50: NA | H50: 74.545046 | I50: WNA_ | J50: 0616242750 | K50: M'HAMID , Opération Abwab Al Atlas Imm B6 ,Numéro 11 Bat IMM B9 | L50: =VLOOKUP(A50,#REF!,1,0) -> #REF!
A51: DTLI71036742 | B51: 0529728168 | C51: RTC DTL | D51: VA | E51: NA | H51: 73.397407 | I51: WNA_ | J51: 0626372353 | K51: M'HAMID ,Lotissement M hamid 4 ,Numéro 499 | L51: =VLOOKUP(A51,#REF!,1,0) -> #REF!
A52: DTLI02206624 | B52: 0529715759 | C52: RTC DTL | D52: VA | E52: NA | H52: 70.624479 | I52: WNA_ | J52: 212667237667 | K52: M'HAMID , Lotissement M hamid 2 ,Numéro 24 | L52: =VLOOKUP(A52,#REF!,1,0) -> #REF!
A53: 99482279 | B53: 0524361444 | C53: RTC | D53: VA | E53: TR | H53: 68.924132 | I53: EDDACHRAOUIFATIMA | J53: 000000000 | K53: M'HAMID ,Op-Jardins des Orangier Imm D2 ,Etage 1 Porte 8
A54: DTLI71045690 | B54: 0529717351 | C54: RTC DTL | D54: VA | E54: NA | H54: 68.863669 | I54: WNA_ | J54: 0701201631 | K54: M'HAMID ,Lotissement Adrar I ,Numéro 60 | L54: =VLOOKUP(A54,#REF!,1,0) -> #REF!
A55: DTLI02206981 | B55: 0529737462 | C55: RTC DTL | D55: VA | E55: NA | H55: 64.51794 | I55: WNA_ | J55: 212630870058 | K55: M'HAMID ,Lotissement Saada 1 ,Numéro 368 | L55: =VLOOKUP(A55,#REF!,1,0) -> #REF!
A56: DTLI71057362 | B56: 0529720428 | C56: RTC DTL | D56: VA | E56: NA | F56: TRSA | G56: TR saturé Mha:142 | H56: 64.462361 | I56: WNA_ | J56: 212663804910 | K56: BOUAAKAZ , Opération Bahia Sakane Imm 69 ,Numéro 3220 | L56: =VLOOKUP(A56,#REF!,1,0) -> #REF!
A57: DTLI71065037 | B57: 0529740107 | C57: RTC DTL | D57: VA | E57: NA | H57: 62.559248 | I57: WNA_ | J57: 0662845144 | K57: OPERATION DOHA BORJ AZZAYTOUN , Immeuble GH01-004 ,Numéro imm 4 Bat 10 | L57: =VLOOKUP(A57,#REF!,1,0) -> #REF!
A58: DTLIO00DA619 | B58: 0525316158 | C58: RTC DTL | D58: VA | E58: NA | H58: 61.829826 | I58: MARMT_ | J58: 0615334752 | K58: M'HAMID ,Résidence Noha GH3 Imm 4 ,Numéro 45 Bat 15 | L58: =VLOOKUP(A58,#REF!,1,0) -> #REF!
A59: DTLI71068038 | B59: 0529590306 | C59: RTC DTL | D59: VA | E59: NA | H59: 61.817998 | I59: WNA_ | J59: 212661183621 | K59: M'HAMID , Opération les Jardins d'Anas ,Numéro imm o Bat 1 | L59: =VLOOKUP(A59,#REF!,1,0) -> #REF!
A60: DTLI71070897 | B60: 0529440699 | C60: RTC DTL | D60: VA | E60: NA | H60: 60.805116 | I60: WNA_ | J60: 0771555499 | K60: M'HAMID ,Lotissement M'hamid 9 ,Numéro 74 | L60: =VLOOKUP(A60,#REF!,1,0) -> #REF!
A61: DTLI71074202 | B61: 0529744104 | C61: RTC DTL | D61: VA | E61: NA | H61: 59.671019 | I61: WNA_ | J61: 0662778805 | K61: M'HAMID ,Lotissement M hamid 5 ,Numéro 1066 | L61: =VLOOKUP(A61,#REF!,1,0) -> #REF!
A62: DTLI71078058 | B62: 0529737599 | C62: RTC DTL | D62: VA | E62: NA | H62: 57.546076 | I62: WNA_ | J62: 212626288009 | K62: M'HAMID , Opération El Bahja ,Numéro 9 | L62: =VLOOKUP(A62,#REF!,1,0) -> #REF!
A63: DTLIO00DBB63 | B63: 0525317504 | C63: RTC DTL | D63: VA | E63: NA | H63: 56.624375 | I63: MARMT_ | J63: 0670417703 | K63: M'HAMID ,Lotissement Maatallah ,Numéro 2257 Bat 15 | L63: =VLOOKUP(A63,#REF!,1,0) -> #REF!
A64: DTLI71081239 | B64: 0529744272 | C64: RTC DTL | D64: VA | E64: NA | H64: 55.871493 | I64: WNA_ | J64: 212696175750 | K64: M'HAMID , Opération Borj Ali Imm A M'hamid 9 ,Numéro 5 | L64: =VLOOKUP(A64,#REF!,1,0) -> #REF!
A65: DTLI71082468 | B65: 0529451947 | C65: RTC DTL | D65: VA | E65: NA | H65: 55.625081 | I65: WNA_ | J65: 0666732403 | K65: M'HAMID ,Lotissement Maatallah ,Numéro 74 | L65: =VLOOKUP(A65,#REF!,1,0) -> #REF!
A66: DTLI71086760 | B66: 0529751247 | C66: RTC DTL | D66: VA | E66: NA | H66: 54.640208 | I66: WNA_ | J66: 0633211649 | K66: M'HAMID , Lotissement Berradi II ,Numéro 610 | L66: =VLOOKUP(A66,#REF!,1,0) -> #REF!
...

Sheet SITUATION19
A1: N° Com. | B1: ND | C1: S. Produit | D1: Etat | E1: Op | F1: Motif | G1: com. motif | H1: Délai(j) | I1: Intitulé client | J1: Contact client | K1: Adresse | L1: A
A2: DTLI70641411 | B2: 0529418093 | C2: RTC DTL | D2: VA | E2: NA | H2: 211.5174 | I2: WNA_ | J2: 0641373034 | K2: M'HAMID ,Lotissement Al Housna ,Porte 372 | L2: =VLOOKUP(A2,#REF!,1,0) -> #REF!
A3: DTLI70727850 | B3: 0529609744 | C3: RTC DTL | D3: VA | E3: NA | F3: CRI | H3: 186.39736 | I3: WNA_ | J3: 0671369895 | K3: BOUAAKAZ , Opération Bahia Sakane Imm 64 ,Numéro 19 | L3: =VLOOKUP(A3,#REF!,1,0) -> #REF!
A4: DTLI70734641 | B4: 0529647012 | C4: RTC DTL | D4: VA | E4: NA | H4: 183.45184 | I4: WNA_ | J4: 0708917890 | K4: M'HAMID , Les jardins d Abrar GH3-Imm28 ,Numéro 29 | L4: =VLOOKUP(A4,#REF!,1,0) -> #REF!
A5: DTLIO00BBED7 | B5: 0520960948 | C5: RTC DTL | D5: VA | E5: NA | H5: 177.86016 | I5: MARMT_ | J5: 0641080135 | K5: M'HAMID , Lotissement Berradi II ,Numéro 493 | L5: =VLOOKUP(A5,#REF!,1,0) -> #REF!
A6: DTLI70808185 | B6: 0529580630 | C6: RTC DTL | D6: VA | E6: NA | H6: 158.71365 | I6: WNA_ | J6: 0626972101 | K6: M'HAMID , Bloc 19 ,Numéro 725 | L6: =VLOOKUP(A6,#REF!,1,0) -> #REF!
A7: DTLI70815011 | B7: 0529591519 | C7: RTC DTL | D7: VA | E7: NA | H7: 156.555 | I7: WNA_ | J7: 0624096534 | K7: M'HAMID , Op Abwab Al Atlas Imm B3 ,Numéro 40 | L7: =VLOOKUP(A7,#REF!,1,0) -> #REF!
A8: DTLI70822536 | B8: 529410591 | C8: RTC DTL | D8: VA | E8: NA | H8: 153.7698 | I8: WNA_ | J8: 0696365109 | K8: BOUAAKAZ ,Bloc 12 ,Numéro 583 | L8: =VLOOKUP(A8,#REF!,1,0) -> #REF!
A9: DTLI70823120 | B9: 0529429466 | C9: RTC DTL | D9: VA | E9: NA | H9: 153.65277 | I9: WNA_ | J9: 212661744871 | K9: BOUAAKAZ , Opération Bahia Sakane Imm 73 ,Numéro 1065 | L9: =VLOOKUP(A9,#REF!,1,0) -> #REF!
A10: DTLI70831392 | B10: 0529432499 | C10: RTC DTL | D10: VA | E10: NA | H10: 151.51706 | I10: WNA_ | J10: 0694778288 | K10: Province M'HAMID ,Opération les Jardins d'Anas Imm E1 ,Numéro 18 | L10: =VLOOKUP(A10,#REF!,1,0) -> #REF!
A11: DTLI70834878 | B11: 0529440893 | C11: RTC DTL | D11: VA | E11: NA | H11: 149.41674 | I11: WNA_ | J11: 212661940825 | K11: M'HAMID , Opération Diour Atlas Imm V ,Numéro 11 Bat imm w | L11: =VLOOKUP(A11,#REF!,1,0) -> #REF!
A12: DTLI70848819 | B12: 0529445356 | C12: RTC DTL | D12: VA | E12: NA | H12: 145.53113 | I12: WNA_ | J12: 0669334904 | K12: M'HAMID , Les jardins d Abrar GH5-Imm47 ,Numéro 5 | L12: =VLOOKUP(A12,#REF!,1,0) -> #REF!
A13: DTLI70855365 | B13: 0529447317 | C13: RTC DTL | D13: VA | E13: NA | H13: 142.78405 | I13: WNA_ | J13: 212670423087 | K13: M'HAMID ,Lotissement Saada 2 ,Numéro 863 | L13: =VLOOKUP(A13,#REF!,1,0) -> #REF!
A14: DTLIO00C5AD5 | B14: 0525294318 | C14: RTC DTL | D14: VA | E14: NA | H14: 142.53978 | I14: MARMT_ | J14: 0684466786 | K14: M'HAMID , Opération Diour Atlas Imm J ,Numéro 12 Bat IMM V | L14: =VLOOKUP(A14,#REF!,1,0) -> #REF!
A15: DTLIO00C5738 | B15: 0525294069 | C15: RTC DTL | D15: VA | E15: NA | H15: 141.89973 | I15: MARMT_ | J15: 0634669071 | K15: M'HAMID ,Opération Al Bassatine Bloc A ,Numéro 1 Bat 15 | L15: =VLOOKUP(A15,#REF!,1,0) -> #REF!
A16: DTLI70860498 | B16: 0529449243 | C16: RTC DTL | D16: VA | E16: NA | H16: 140.87677 | I16: WNA_ | J16: 212671208444 | K16: M'HAMID , Opération Diour Masjid GH1- Imm1 ,Porte 17 | L16: =VLOOKUP(A16,#REF!,1,0) -> #REF!
A17: DTLI70874878 | B17: 0529455507 | C17: RTC DTL | D17: VA | E17: NA | H17: 135.61127 | I17: WNA_ | J17: 212672749642 | K17: M'HAMID ,Bloc 19 ,Numéro 703 | L17: =VLOOKUP(A17,#REF!,1,0) -> #REF!
A18: DTLI70883534 | B18: 0529458730 | C18: RTC DTL | D18: VA | E18: NA | H18: 132.7424 | I18: WNA_ | J18: 0668762249 | K18: OPERATION DOHA BORJ AZZAYTOUN ,Immeuble GH01-013 ,Numéro 1 | L18: =VLOOKUP(A18,#REF!,1,0) -> #REF!
A19: DTLIO00C9AEA | B19: 0525297958 | C19: RTC DTL | D19: VA | E19: NA | H19: 128.49644 | I19: MARMT_ | J19: 0693845114 | K19: M'HAMID ,Lotissement Al Housna ,Numéro 150 Bat 15 | L19: =VLOOKUP(A19,#REF!,1,0) -> #REF!
A20: DTLI70906912 | B20: 0529469611 | C20: RTC DTL | D20: VA | E20: NA | H20: 126.51146 | I20: WNA_ | J20: 0660241899 | K20: M'HAMID , Ain Souna Imm A1 ,Numéro MAGAZIN 2 | L20: =VLOOKUP(A20,#REF!,1,0) -> #REF!
... A42: DTLI70994638 | B42: 0529712093 | C42: RTC DTL | D42: VA | E42: NA | H42: 93.710104 | I42: WNA_ | J42: 0648684341 | K42: M'HAMID ,Bloc 26 ,Numéro 1191 | L42: =VLOOKUP(A42,#REF!,1,0) -> #REF!
A43: 99407301 | B43: 0524379905 | C43: RTC | D43: VA | E43: NA | F43: EBST | H43: 92.868264 | I43: AOUTARABDELALI | J43: 0661746605 | K43: M'HAMID ,Bassatine Mrkch GH4-Imm 20U Mhamid9 ,Numéro 5 Etage 3
A44: DTLI70996673 | B44: 0529712877 | C44: RTC DTL | D44: VA | E44: NA | H44: 92.780937 | I44: WNA_ | J44: 212635710367 | K44: M'HAMID , Opération Salama GHI-Imm3 ,Numéro 3 Bat BLOC H IMM 03 | L44: =VLOOKUP(A44,#REF!,1,0) -> #REF!
A45: DTLI70997241 | B45: 0529713551 | C45: RTC DTL | D45: VA | E45: NA | H45: 92.710961 | I45: WNA_ | J45: 0657162022 | K45: M'HAMID ,Lotissement Al Housna ,Numéro 464 | L45: =VLOOKUP(A45,#REF!,1,0) -> #REF!
A46: DTLI70998954 | B46: 0529714279 | C46: RTC DTL | D46: VA | E46: NA | H46: 91.7939 | I46: WNA_ | J46: 212660971142 | K46: M'HAMID ,Lotissement Saada 1 ,Numéro 445 | L46: =VLOOKUP(A46,#REF!,1,0) -> #REF!
A47: DTLI71003402 | B47: 0529715890 | C47: RTC DTL | D47: VA | E47: NA | H47: 90.351412 | I47: WNA_ | J47: 0601409696 | K47: M'HAMID , Lotissement M hamid 2 ,Numéro 1564 | L47: =VLOOKUP(A47,#REF!,1,0) -> #REF!
A48: DTLI71014644 | B48: 0529719258 | C48: RTC DTL | D48: VA | E48: NA | H48: 85.387894 | I48: WNA_ | J48: 0663298214 | K48: BOUAAKAZ , Voie Inconnue ,Numéro RES KORTOBA IMM F N 8 | L48: =VLOOKUP(A48,#REF!,1,0) -> #REF!
A49: DTLI71030474 | B49: 0529724741 | C49: RTC DTL | D49: VA | E49: NA | H49: 76.823275 | I49: WNA_ | J49: 212632774634 | K49: M'HAMID , Lotissement M'hamid 9 ,Numéro 509 | L49: =VLOOKUP(A49,#REF!,1,0) -> #REF!
A50: DTLI71034419 | B50: 0529726562 | C50: RTC DTL | D50: VA | E50: NA | H50: 75.546481 | I50: WNA_ | J50: 0616242750 | K50: M'HAMID , Opération Abwab Al Atlas Imm B6 ,Numéro 11 Bat IMM B9 | L50: =VLOOKUP(A50,#REF!,1,0) -> #REF!
A51: DTLI71036742 | B51: 0529728168 | C51: RTC DTL | D51: VA | E51: NA | H51: 74.398843 | I51: WNA_ | J51: 0626372353 | K51: M'HAMID ,Lotissement M hamid 4 ,Numéro 499 | L51: =VLOOKUP(A51,#REF!,1,0) -> #REF!
A52: DTLI02206624 | B52: 0529715759 | C52: RTC DTL | D52: VA | E52: NA | H52: 71.625914 | I52: WNA_ | J52: 212667237667 | K52: M'HAMID , Lotissement M hamid 2 ,Numéro 24 | L52: =VLOOKUP(A52,#REF!,1,0) -> #REF!
A53: 99482279 | B53: 0524361444 | C53: RTC | D53: VA | E53: TR | H53: 69.925567 | I53: EDDACHRAOUIFATIMA | J53: 000000000 | K53: M'HAMID ,Op-Jardins des Orangier Imm D2 ,Etage 1 Porte 8
A54: DTLI71045690 | B54: 0529717351 | C54: RTC DTL | D54: VA | E54: NA | H54: 69.865104 | I54: WNA_ | J54: 0701201631 | K54: M'HAMID ,Lotissement Adrar I ,Numéro 60 | L54: =VLOOKUP(A54,#REF!,1,0) -> #REF!
A55: DTLI02206981 | B55: 0529737462 | C55: RTC DTL | D55: VA | E55: NA | H55: 65.519375 | I55: WNA_ | J55: 212630870058 | K55: M'HAMID ,Lotissement Saada 1 ,Numéro 368 | L55: =VLOOKUP(A55,#REF!,1,0) -> #REF!
A56: DTLI71057362 | B56: 0529720428 | C56: RTC DTL | D56: VA | E56: NA | F56: TRSA | G56: TR saturé Mha:142 | H56: 65.463796 | I56: WNA_ | J56: 212663804910 | K56: BOUAAKAZ , Opération Bahia Sakane Imm 69 ,Numéro 3220 | L56: =VLOOKUP(A56,#REF!,1,0) -> #REF!
A57: DTLI71065037 | B57: 0529740107 | C57: RTC DTL | D57: VA | E57: NA | H57: 63.560683 | I57: WNA_ | J57: 0662845144 | K57: OPERATION DOHA BORJ AZZAYTOUN , Immeuble GH01-004 ,Numéro imm 4 Bat 10 | L57: =VLOOKUP(A57,#REF!,1,0) -> #REF!
A58: DTLIO00DA619 | B58: 0525316158 | C58: RTC DTL | D58: VA | E58: NA | H58: 62.831262 | I58: MARMT_ | J58: 0615334752 | K58: M'HAMID ,Résidence Noha GH3 Imm 4 ,Numéro 45 Bat 15 | L58: =VLOOKUP(A58,#REF!,1,0) -> #REF!
A59: DTLI71068038 | B59: 0529590306 | C59: RTC DTL | D59: VA | E59: NA | H59: 62.819433 | I59: WNA_ | J59: 212661183621 | K59: M'HAMID , Opération les Jardins d'Anas ,Numéro imm o Bat 1 | L59: =VLOOKUP(A59,#REF!,1,0) -> #REF!
A60: DTLI71070897 | B60: 0529440699 | C60: RTC DTL | D60: VA | E60: NA | H60: 61.806551 | I60: WNA_ | J60: 0771555499 | K60: M'HAMID ,Lotissement M'hamid 9 ,Numéro 74 | L60: =VLOOKUP(A60,#REF!,1,0) -> #REF!
A61: DTLI71074202 | B61: 0529744104 | C61: RTC DTL | D61: VA | E61: NA | H61: 60.672454 | I61: WNA_ | J61: 0662778805 | K61: M'HAMID ,Lotissement M hamid 5 ,Numéro 1066 | L61: =VLOOKUP(A61,#REF!,1,0) -> #REF!
...

Sheet SITUATION20
A1: N° Com. | B1: ND | C1: S. Produit | D1: Etat | E1: Op | F1: Motif | G1: com. Motif | H1: Délai(j) | I1: Intitulé client | J1: Contact client | K1: Adresse | L1: A
A2: DTLI70641411 | B2: 0529418093 | C2: RTC DTL | D2: VA | E2: NA | H2: 212.51612 | I2: WNA_ | J2: 0641373034 | K2: M'HAMID ,Lotissement Al Housna ,Porte 372 | L2: =VLOOKUP(A2,#REF!,1,0) -> #REF!
A3: DTLI70727850 | B3: 0529609744 | C3: RTC DTL | D3: VA | E3: NA | F3: CRI | H3: 187.39609 | I3: WNA_ | J3: 0671369895 | K3: BOUAAKAZ , Opération Bahia Sakane Imm 64 ,Numéro 19 | L3: =VLOOKUP(A3,#REF!,1,0) -> #REF!
A4: DTLI70734641 | B4: 0529647012 | C4: RTC DTL | D4: VA | E4: NA | H4: 184.45057 | I4: WNA_ | J4: 0708917890 | K4: M'HAMID , Les jardins d Abrar GH3-Imm28 ,Numéro 29 | L4: =VLOOKUP(A4,#REF!,1,0) -> #REF!
A5: DTLIO00BBED7 | B5: 0520960948 | C5: RTC DTL | D5: VA | E5: NA | H5: 178.85889 | I5: MARMT_ | J5: 0641080135 | K5: M'HAMID , Lotissement Berradi II ,Numéro 493 | L5: =VLOOKUP(A5,#REF!,1,0) -> #REF!
A6: DTLI70808185 | B6: 0529580630 | C6: RTC DTL | D6: VA | E6: NA | H6: 159.71237 | I6: WNA_ | J6: 0626972101 | K6: M'HAMID , Bloc 19 ,Numéro 725 | L6: =VLOOKUP(A6,#REF!,1,0) -> #REF!
A7: DTLI70815011 | B7: 0529591519 | C7: RTC DTL | D7: VA | E7: NA | H7: 157.55373 | I7: WNA_ | J7: 0624096534 | K7: M'HAMID , Op Abwab Al Atlas Imm B3 ,Numéro 40 | L7: =VLOOKUP(A7,#REF!,1,0) -> #REF!
A8: DTLI70822536 | B8: 0529410591 | C8: RTC DTL | D8: VA | E8: NA | H8: 154.76853 | I8: WNA_ | J8: 0696365109 | K8: BOUAAKAZ ,Bloc 12 ,Numéro 583 | L8: =VLOOKUP(A8,#REF!,1,0) -> #REF!
A9: DTLI70823120 | B9: 0529429466 | C9: RTC DTL | D9: VA | E9: NA | H9: 154.65149 | I9: WNA_ | J9: 212661744871 | K9: BOUAAKAZ , Opération Bahia Sakane Imm 73 ,Numéro 1065 | L9: =VLOOKUP(A9,#REF!,1,0) -> #REF!
A10: DTLI70831392 | B10: 0529432499 | C10: RTC DTL | D10: VA | E10: NA | H10: 152.51579 | I10: WNA_ | J10: 0694778288 | K10: Province M'HAMID ,Opération les Jardins d'Anas Imm E1 ,Numéro 18 | L10: =VLOOKUP(A10,#REF!,1,0) -> #REF!
A11: DTLI70834878 | B11: 0529440893 | C11: RTC DTL | D11: VA | E11: NA | H11: 150.41546 | I11: WNA_ | J11: 212661940825 | K11: M'HAMID , Opération Diour Atlas Imm V ,Numéro 11 Bat imm w | L11: =VLOOKUP(A11,#REF!,1,0) -> #REF!
A12: DTLI70848819 | B12: 0529445356 | C12: RTC DTL | D12: VA | E12: NA | H12: 146.52986 | I12: WNA_ | J12: 0669334904 | K12: M'HAMID , Les jardins d Abrar GH5-Imm47 ,Numéro 5 | L12: =VLOOKUP(A12,#REF!,1,0) -> #REF!
A13: DTLI70855365 | B13: 0529447317 | C13: RTC DTL | D13: VA | E13: NA | H13: 143.78278 | I13: WNA_ | J13: 212670423087 | K13: M'HAMID ,Lotissement Saada 2 ,Numéro 863 | L13: =VLOOKUP(A13,#REF!,1,0) -> #REF!
A14: DTLIO00C5AD5 | B14: 0525294318 | C14: RTC DTL | D14: VA | E14: NA | H14: 143.53851 | I14: MARMT_ | J14: 0684466786 | K14: M'HAMID , Opération Diour Atlas Imm J ,Numéro 12 Bat IMM V | L14: =VLOOKUP(A14,#REF!,1,0) -> #REF!
A15: DTLIO00C5738 | B15: 0525294069 | C15: RTC DTL | D15: VA | E15: NA | H15: 142.89846 | I15: MARMT_ | J15: 0634669071 | K15: M'HAMID ,Opération Al Bassatine Bloc A ,Numéro 1 Bat 15 | L15: =VLOOKUP(A15,#REF!,1,0) -> #REF!
... A42: DTLI70994638 | B42: 0529712093 | C42: RTC DTL | D42: VA | E42: NA | H42: 94.708831 | I42: WNA_ | J42: 0648684341 | K42: M'HAMID ,Bloc 26 ,Numéro 1191 | L42: =VLOOKUP(A42,#REF!,1,0) -> #REF!
A43: 99407301 | B43: 0524379905 | C43: RTC | D43: VA | E43: NA | F43: EBST | H43: 93.866991 | I43: AOUTARABDELALI | J43: 0661746605 | K43: M'HAMID ,Bassatine Mrkch GH4-Imm 20U Mhamid9 ,Numéro 5 Etage 3
A44: DTLI70996673 | B44: 0529712877 | C44: RTC DTL | D44: VA | E44: NA | H44: 93.779664 | I44: WNA_ | J44: 212635710367 | K44: M'HAMID , Opération Salama GHI-Imm3 ,Numéro 3 Bat BLOC H IMM 03 | L44: =VLOOKUP(A44,#REF!,1,0) -> #REF!
A45: DTLI70997241 | B45: 0529713551 | C45: RTC DTL | D45: VA | E45: NA | H45: 93.709688 | I45: WNA_ | J45: 0657162022 | K45: M'HAMID ,Lotissement Al Housna ,Numéro 464 | L45: =VLOOKUP(A45,#REF!,1,0) -> #REF!
A46: DTLI70998954 | B46: 0529714279 | C46: RTC DTL | D46: VA | E46: NA | H46: 92.792627 | I46: WNA_ | J46: 212660971142 | K46: M'HAMID ,Lotissement Saada 1 ,Numéro 445 | L46: =VLOOKUP(A46,#REF!,1,0) -> #REF!
A47: DTLI71003402 | B47: 0529715890 | C47: RTC DTL | D47: VA | E47: NA | H47: 91.350139 | I47: WNA_ | J47: 0601409696 | K47: M'HAMID , Lotissement M hamid 2 ,Numéro 1564 | L47: =VLOOKUP(A47,#REF!,1,0) -> #REF!
A48: DTLI71014644 | B48: 0529719258 | C48: RTC DTL | D48: VA | E48: NA | H48: 86.38662 | I48: WNA_ | J48: 0663298214 | K48: BOUAAKAZ , Voie Inconnue ,Numéro RES KORTOBA IMM F N 8 | L48: =VLOOKUP(A48,#REF!,1,0) -> #REF!
A49: DTLI71030474 | B49: 0529724741 | C49: RTC DTL | D49: VA | E49: NA | H49: 77.822002 | I49: WNA_ | J49: 212632774634 | K49: M'HAMID , Lotissement M'hamid 9 ,Numéro 509 | L49: =VLOOKUP(A49,#REF!,1,0) -> #REF!
A50: DTLI71034419 | B50: 0529726562 | C50: RTC DTL | D50: VA | E50: NA | H50: 76.545208 | I50: WNA_ | J50: 0616242750 | K50: M'HAMID , Opération Abwab Al Atlas Imm B6 ,Numéro 11 Bat IMM B9 | L50: =VLOOKUP(A50,#REF!,1,0) -> #REF!
A51: DTLI71036742 | B51: 0529728168 | C51: RTC DTL | D51: VA | E51: NA | H51: 75.397569 | I51: WNA_ | J51: 0626372353 | K51: M'HAMID ,Lotissement M hamid 4 ,Numéro 499 | L51: =VLOOKUP(A51,#REF!,1,0) -> #REF!
A52: DTLI02206624 | B52: 0529715759 | C52: RTC DTL | D52: VA | E52: NA | H52: 72.624641 | I52: WNA_ | J52: 212667237667 | K52: M'HAMID , Lotissement M hamid 2 ,Numéro 24 | L52: =VLOOKUP(A52,#REF!,1,0) -> #REF!
A53: 99482279 | B53: 0524361444 | C53: RTC | D53: VA | E53: TR | H53: 70.924294 | I53: EDDACHRAOUIFATIMA | J53: 000000000 | K53: M'HAMID ,Op-Jardins des Orangier Imm D2 ,Etage 1 Porte 8
A54: DTLI71045690 | B54: 0529717351 | C54: RTC DTL | D54: VA | E54: NA | H54: 70.863831 | I54: WNA_ | J54: 0701201631 | K54: M'HAMID ,Lotissement Adrar I ,Numéro 60 | L54: =VLOOKUP(A54,#REF!,1,0) -> #REF!
A55: DTLI02206981 | B55: 0529737462 | C55: RTC DTL | D55: VA | E55: NA | H55: 66.518102 | I55: WNA_ | J55: 212630870058 | K55: M'HAMID ,Lotissement Saada 1 ,Numéro 368 | L55: =VLOOKUP(A55,#REF!,1,0) -> #REF!
A56: DTLI71057362 | B56: 0529720428 | C56: RTC DTL | D56: VA | E56: NA | F56: TRSA | G56: TR saturé Mha:142 | H56: 66.462523 | I56: WNA_ | J56: 212663804910 | K56: BOUAAKAZ , Opération Bahia Sakane Imm 69 ,Numéro 3220 | L56: =VLOOKUP(A56,#REF!,1,0) -> #REF!
A57: DTLI71065037 | B57: 0529740107 | C57: RTC DTL | D57: VA | E57: NA | H57: 64.55941 | I57: WNA_ | J57: 0662845144 | K57: OPERATION DOHA BORJ AZZAYTOUN , Immeuble GH01-004 ,Numéro imm 4 Bat 10 | L57: =VLOOKUP(A57,#REF!,1,0) -> #REF!
A58: DTLIO00DA619 | B58: 0525316158 | C58: RTC DTL | D58: VA | E58: NA | H58: 63.829988 | I58: MARMT_ | J58: 0615334752 | K58: M'HAMID ,Résidence Noha GH3 Imm 4 ,Numéro 45 Bat 15 | L58: =VLOOKUP(A58,#REF!,1,0) -> #REF!
A59: DTLI71068038 | B59: 0529590306 | C59: RTC DTL | D59: VA | E59: NA | H59: 63.81816 | I59: WNA_ | J59: 212661183621 | K59: M'HAMID , Opération les Jardins d'Anas ,Numéro imm o Bat 1 | L59: =VLOOKUP(A59,#REF!,1,0) -> #REF!
A60: DTLI71070897 | B60: 0529440699 | C60: RTC DTL | D60: VA | E60: NA | H60: 62.805278 | I60: WNA_ | J60: 0771555499 | K60: M'HAMID ,Lotissement M'hamid 9 ,Numéro 74 | L60: =VLOOKUP(A60,#REF!,1,0) -> #REF!
A61: DTLI71074202 | B61: 0529744104 | C61: RTC DTL | D61: VA | E61: NA | H61: 61.671181 | I61: WNA_ | J61: 0662778805 | K61: M'HAMID ,Lotissement M hamid 5 ,Numéro 1066 | L61: =VLOOKUP(A61,#REF!,1,0) -> #REF!
A62: DTLI71078058 | B62: 0529737599 | C62: RTC DTL | D62: VA | E62: NA | H62: 59.546238 | I62: WNA_ | J62: 212626288009 | K62: M'HAMID , Opération El Bahja ,Numéro 9 | L62: =VLOOKUP(A62,#REF!,1,0) -> #REF!
A63: DTLIO00DBB63 | B63: 0525317504 | C63: RTC DTL | D63: VA | E63: NA | H63: 58.624537 | I63: MARMT_ | J63: 0670417703 | K63: M'HAMID ,Lotissement Maatallah ,Numéro 2257 Bat 15 | L63: =VLOOKUP(A63,#REF!,1,0) -> #REF!
A64: DTLI71081239 | B64: 0529744272 | C64: RTC DTL | D64: VA | E64: NA | H64: 57.871655 | I64: WNA_ | J64: 212696175750 | K64: M'HAMID , Opération Borj Ali Imm A M'hamid 9 ,Numéro 5 | L64: =VLOOKUP(A64,#REF!,1,0) -> #REF!
A65: DTLI71082468 | B65: 0529451947 | C65: RTC DTL | D65: VA | E65: NA | H65: 57.625243 | I65: WNA_ | J65: 0666732403 | K65: M'HAMID ,Lotissement Maatallah ,Numéro 74 | L65: =VLOOKUP(A65,#REF!,1,0) -> #REF!
A66: DTLI71086760 | B66: 0529751247 | C66: RTC DTL | D66: VA | E66: NA | H66: 56.64037 | I66: WNA_ | J66: 0633211649 | K66: M'HAMID , Lotissement Berradi II ,Numéro 610 | L66: =VLOOKUP(A66,#REF!,1,0) -> #REF!
...

Sheet SITUATION21
A1: N° Com. | B1: ND | C1: S. Produit | D1: Etat | E1: Op | F1: Motif | G1: com. motif | H1: Délai(j) | I1: Intitulé client | J1: Contact client | K1: Adresse | L1: A
A2: DTLI70641411 | B2: 0529418093 | C2: RTC DTL | D2: VA | E2: NA | H2: 213.51617 | I2: WNA_ | J2: 0641373034 | K2: M'HAMID ,Lotissement Al Housna ,Porte 372 | L2: =VLOOKUP(A2,#REF!,1,0) -> #REF!
A3: DTLI70727850 | B3: 0529609744 | C3: RTC DTL | D3: VA | E3: NA | F3: CRI | H3: 188.39613 | I3: WNA_ | J3: 0671369895 | K3: BOUAAKAZ , Opération Bahia Sakane Imm 64 ,Numéro 19 | L3: =VLOOKUP(A3,#REF!,1,0) -> #REF!
A4: DTLI70734641 | B4: 0529647012 | C4: RTC DTL | D4: VA | E4: NA | H4: 185.45061 | I4: WNA_ | J4: 0708917890 | K4: M'HAMID , Les jardins d Abrar GH3-Imm28 ,Numéro 29 | L4: =VLOOKUP(A4,#REF!,1,0) -> #REF!
A5: DTLIO00BBED7 | B5: 0520960948 | C5: RTC DTL | D5: VA | E5: NA | H5: 179.85894 | I5: MARMT_ | J5: 0641080135 | K5: M'HAMID , Lotissement Berradi II ,Numéro 493 | L5: =VLOOKUP(A5,#REF!,1,0) -> #REF!
A6: DTLI70808185 | B6: 0529580630 | C6: RTC DTL | D6: VA | E6: NA | H6: 160.71242 | I6: WNA_ | J6: 0626972101 | K6: M'HAMID , Bloc 19 ,Numéro 725 | L6: =VLOOKUP(A6,#REF!,1,0) -> #REF!
A7: DTLI70815011 | B7: 0529591519 | C7: RTC DTL | D7: VA | E7: NA | H7: 158.55377 | I7: WNA_ | J7: 0624096534 | K7: M'HAMID , Op Abwab Al Atlas Imm B3 ,Numéro 40 | L7: =VLOOKUP(A7,#REF!,1,0) -> #REF!
A8: DTLI70822536 | B8: 0529410591 | C8: RTC DTL | D8: VA | E8: NA | H8: 155.76858 | I8: WNA_ | J8: 0696365109 | K8: BOUAAKAZ ,Bloc 12 ,Numéro 583 | L8: =VLOOKUP(A8,#REF!,1,0) -> #REF!
A9: DTLI70823120 | B9: 0529429466 | C9: RTC DTL | D9: VA | E9: NA | H9: 155.65154 | I9: WNA_ | J9: 212661744871 | K9: BOUAAKAZ , Opération Bahia Sakane Imm 73 ,Numéro 1065 | L9: =VLOOKUP(A9,#REF!,1,0) -> #REF!
A10: DTLI70831392 | B10: 0529432499 | C10: RTC DTL | D10: VA | E10: NA | H10: 153.51583 | I10: WNA_ | J10: 0694778288 | K10: Province M'HAMID ,Opération les Jardins d'Anas Imm E1 ,Numéro 18 | L10: =VLOOKUP(A10,#REF!,1,0) -> #REF!
A11: DTLI70834878 | B11: 0529440893 | C11: RTC DTL | D11: VA | E11: NA | H11: 151.41551 | I11: WNA_ | J11: 212661940825 | K11: M'HAMID , Opération Diour Atlas Imm V ,Numéro 11 Bat imm w | L11: =VLOOKUP(A11,#REF!,1,0) -> #REF!
A12: DTLI70848819 | B12: 0529445356 | C12: RTC DTL | D12: VA | E12: NA | H12: 147.52991 | I12: WNA_ | J12: 0669334904 | K12: M'HAMID , Les jardins d Abrar GH5-Imm47 ,Numéro 5 | L12: =VLOOKUP(A12,#REF!,1,0) -> #REF!
A13: DTLI70855365 | B13: 0529447317 | C13: RTC DTL | D13: VA | E13: NA | H13: 144.78282 | I13: WNA_ | J13: 212670423087 | K13: M'HAMID ,Lotissement Saada 2 ,Numéro 863 | L13: =VLOOKUP(A13,#REF!,1,0) -> #REF!
A14: DTLIO00C5AD5 | B14: 0525294318 | C14: RTC DTL | D14: VA | E14: NA | H14: 144.53855 | I14: MARMT_ | J14: 0684466786 | K14: M'HAMID , Opération Diour Atlas Imm J ,Numéro 12 Bat IMM V | L14: =VLOOKUP(A14,#REF!,1,0) -> #REF!
A15: DTLIO00C5738 | B15: 0525294069 | C15: RTC DTL | D15: VA | E15: NA | H15: 143.89851 | I15: MARMT_ | J15: 0634669071 | K15: M'HAMID ,Opération Al Bassatine Bloc A ,Numéro 1 Bat 15 | L15: =VLOOKUP(A15,#REF!,1,0) -> #REF!
... A42: DTLI70994638 | B42: 0529712093 | C42: RTC DTL | D42: VA | E42: NA | H42: 95.708877 | I42: WNA_ | J42: 0648684341 | K42: M'HAMID ,Bloc 26 ,Numéro 1191 | L42: =VLOOKUP(A42,#REF!,1,0) -> #REF!
A43: 99407301 | B43: 0524379905 | C43: RTC | D43: VA | E43: NA | F43: EBST | H43: 94.867037 | I43: AOUTARABDELALI | J43: 0661746605 | K43: M'HAMID ,Bassatine Mrkch GH4-Imm 20U Mhamid9 ,Numéro 5 Etage 3
A44: DTLI70996673 | B44: 0529712877 | C44: RTC DTL | D44: VA | E44: NA | H44: 94.779711 | I44: WNA_ | J44: 212635710367 | K44: M'HAMID , Opération Salama GHI-Imm3 ,Numéro 3 Bat BLOC H IMM 03 | L44: =VLOOKUP(A44,#REF!,1,0) -> #REF!
A45: DTLI70997241 | B45: 0529713551 | C45: RTC DTL | D45: VA | E45: NA | H45: 94.709734 | I45: WNA_ | J45: 0657162022 | K45: M'HAMID ,Lotissement Al Housna ,Numéro 464 | L45: =VLOOKUP(A45,#REF!,1,0) -> #REF!
A46: DTLI70998954 | B46: 0529714279 | C46: RTC DTL | D46: VA | E46: NA | H46: 93.792674 | I46: WNA_ | J46: 212660971142 | K46: M'HAMID ,Lotissement Saada 1 ,Numéro 445 | L46: =VLOOKUP(A46,#REF!,1,0) -> #REF!
A47: DTLI71003402 | B47: 0529715890 | C47: RTC DTL | D47: VA | E47: NA | H47: 92.350185 | I47: WNA_ | J47: 0601409696 | K47: M'HAMID , Lotissement M hamid 2 ,Numéro 1564 | L47: =VLOOKUP(A47,#REF!,1,0) -> #REF!
A48: DTLI71014644 | B48: 0529719258 | C48: RTC DTL | D48: VA | E48: NA | H48: 87.386667 | I48: WNA_ | J48: 0663298214 | K48: BOUAAKAZ , Voie Inconnue ,Numéro RES KORTOBA IMM F N 8 | L48: =VLOOKUP(A48,#REF!,1,0) -> #REF!
A49: DTLI71030474 | B49: 0529724741 | C49: RTC DTL | D49: VA | E49: NA | H49: 78.822049 | I49: WNA_ | J49: 212632774634 | K49: M'HAMID , Lotissement M'hamid 9 ,Numéro 509 | L49: =VLOOKUP(A49,#REF!,1,0) -> #REF!
A50: DTLI71034419 | B50: 0529726562 | C50: RTC DTL | D50: VA | E50: NA | H50: 77.545255 | I50: WNA_ | J50: 0616242750 | K50: M'HAMID , Opération Abwab Al Atlas Imm B6 ,Numéro 11 Bat IMM B9 | L50: =VLOOKUP(A50,#REF!,1,0) -> #REF!
A51: DTLI71036742 | B51: 0529728168 | C51: RTC DTL | D51: VA | E51: NA | H51: 76.397616 | I51: WNA_ | J51: 0626372353 | K51: M'HAMID ,Lotissement M hamid 4 ,Numéro 499 | L51: =VLOOKUP(A51,#REF!,1,0) -> #REF!
A52: DTLI02206624 | B52: 0529715759 | C52: RTC DTL | D52: VA | E52: NA | H52: 73.624687 | I52: WNA_ | J52: 212667237667 | K52: M'HAMID , Lotissement M hamid 2 ,Numéro 24 | L52: =VLOOKUP(A52,#REF!,1,0) -> #REF!
A53: 99482279 | B53: 0524361444 | C53: RTC | D53: VA | E53: TR | H53: 71.92434 | I53: EDDACHRAOUIFATIMA | J53: 000000000 | K53: M'HAMID ,Op-Jardins des Orangier Imm D2 ,Etage 1 Porte 8
A54: DTLI71045690 | B54: 0529717351 | C54: RTC DTL | D54: VA | E54: NA | H54: 71.863877 | I54: WNA_ | J54: 0701201631 | K54: M'HAMID ,Lotissement Adrar I ,Numéro 60 | L54: =VLOOKUP(A54,#REF!,1,0) -> #REF!
A55: DTLI02206981 | B55: 0529737462 | C55: RTC DTL | D55: VA | E55: NA | H55: 67.518148 | I55: WNA_ | J55: 212630870058 | K55: M'HAMID ,Lotissement Saada 1 ,Numéro 368 | L55: =VLOOKUP(A55,#REF!,1,0) -> #REF!
A56: DTLI71057362 | B56: 0529720428 | C56: RTC DTL | D56: VA | E56: NA | F56: TRSA | G56: TR saturé Mha:142 | H56: 67.462569 | I56: WNA_ | J56: 212663804910 | K56: BOUAAKAZ , Opération Bahia Sakane Imm 69 ,Numéro 3220 | L56: =VLOOKUP(A56,#REF!,1,0) -> #REF!
A57: DTLI71065037 | B57: 0529740107 | C57: RTC DTL | D57: VA | E57: NA | H57: 65.559456 | I57: WNA_ | J57: 0662845144 | K57: OPERATION DOHA BORJ AZZAYTOUN , Immeuble GH01-004 ,Numéro imm 4 Bat 10 | L57: =VLOOKUP(A57,#REF!,1,0) -> #REF!
A58: DTLIO00DA619 | B58: 0525316158 | C58: RTC DTL | D58: VA | E58: NA | H58: 64.830035 | I58: MARMT_ | J58: 0615334752 | K58: M'HAMID ,Résidence Noha GH3 Imm 4 ,Numéro 45 Bat 15 | L58: =VLOOKUP(A58,#REF!,1,0) -> #REF!
A59: DTLI71068038 | B59: 0529590306 | C59: RTC DTL | D59: VA | E59: NA | H59: 64.818206 | I59: WNA_ | J59: 212661183621 | K59: M'HAMID , Opération les Jardins d'Anas ,Numéro imm o Bat 1 | L59: =VLOOKUP(A59,#REF!,1,0) -> #REF!
A60: DTLI71070897 | B60: 0529440699 | C60: RTC DTL | D60: VA | E60: NA | H60: 63.805324 | I60: WNA_ | J60: 0771555499 | K60: M'HAMID ,Lotissement M'hamid 9 ,Numéro 74 | L60: =VLOOKUP(A60,#REF!,1,0) -> #REF!
A61: DTLI71074202 | B61: 0529744104 | C61: RTC DTL | D61: VA | E61: NA | H61: 62.671227 | I61: WNA_ | J61: 0662778805 | K61: M'HAMID ,Lotissement M hamid 5 ,Numéro 1066 | L61: =VLOOKUP(A61,#REF!,1,0) -> #REF!
A62: DTLI71078058 | B62: 0529737599 | C62: RTC DTL | D62: VA | E62: NA | H62: 60.546285 | I62: WNA_ | J62: 212626288009 | K62: M'HAMID , Opération El Bahja ,Numéro 9 | L62: =VLOOKUP(A62,#REF!,1,0) -> #REF!
A63: DTLIO00DBB63 | B63: 0525317504 | C63: RTC DTL | D63: VA | E63: NA | H63: 59.624583 | I63: MARMT_ | J63: 0670417703 | K63: M'HAMID ,Lotissement Maatallah ,Numéro 2257 Bat 15 | L63: =VLOOKUP(A63,#REF!,1,0) -> #REF!
A64: DTLI71081239 | B64: 0529744272 | C64: RTC DTL | D64: VA | E64: NA | H64: 58.871701 | I64: WNA_ | J64: 212696175750 | K64: M'HAMID , Opération Borj Ali Imm A M'hamid 9 ,Numéro 5 | L64: =VLOOKUP(A64,#REF!,1,0) -> #REF!
A65: DTLI71082468 | B65: 0529451947 | C65: RTC DTL | D65: VA | E65: NA | H65: 58.625289 | I65: WNA_ | J65: 0666732403 | K65: M'HAMID ,Lotissement Maatallah ,Numéro 74 | L65: =VLOOKUP(A65,#REF!,1,0) -> #REF!
A66: DTLI71086760 | B66: 0529751247 | C66: RTC DTL | D66: VA | E66: NA | H66: 57.640417 | I66: WNA_ | J66: 0633211649 | K66: M'HAMID , Lotissement Berradi II ,Numéro 610 | L66: =VLOOKUP(A66,#REF!,1,0) -> #REF!
...

Sheet SITUATION21.1
A1: N° Com. | B1: ND | C1: S. Produit | D1: Etat | E1: Op | F1: Motif | G1: com. motif | H1: Délai(j) | I1: Intitulé client | J1: Contact client | K1: Adresse | L1: A
